Traceback (most recent call last):
  File "C:\Users\david\anaconda3\envs\jupyterbook\lib\site-packages\jupyter_cache\executors\utils.py", line 64, in single_nb_execution
    **kwargs,
  File "C:\Users\david\anaconda3\envs\jupyterbook\lib\site-packages\nbclient\client.py", line 1204, in execute
    return NotebookClient(nb=nb, resources=resources, km=km, **kwargs).execute()
  File "C:\Users\david\anaconda3\envs\jupyterbook\lib\site-packages\nbclient\util.py", line 84, in wrapped
    return just_run(coro(*args, **kwargs))
  File "C:\Users\david\anaconda3\envs\jupyterbook\lib\site-packages\nbclient\util.py", line 62, in just_run
    return loop.run_until_complete(coro)
  File "C:\Users\david\anaconda3\envs\jupyterbook\lib\asyncio\base_events.py", line 587, in run_until_complete
    return future.result()
  File "C:\Users\david\anaconda3\envs\jupyterbook\lib\site-packages\nbclient\client.py", line 664, in async_execute
    cell, index, execution_count=self.code_cells_executed + 1
  File "C:\Users\david\anaconda3\envs\jupyterbook\lib\site-packages\nbclient\client.py", line 965, in async_execute_cell
    await self._check_raise_for_error(cell, cell_index, exec_reply)
  File "C:\Users\david\anaconda3\envs\jupyterbook\lib\site-packages\nbclient\client.py", line 862, in _check_raise_for_error
    raise CellExecutionError.from_cell_and_msg(cell, exec_reply_content)
nbclient.exceptions.CellExecutionError: An error occurred while executing the following cell:
------------------
import pandas as pd
import numpy as np
import plotly.graph_objects as go
import plotly.subplots as sp
import plotly.express as px
import plotly.io as io

io.templates.default = 'plotly_dark'

main_dataset = pd.read_pickle('processed_dataset.pkl')
------------------

[1;31m---------------------------------------------------------------------------[0m
[1;31mValueError[0m                                Traceback (most recent call last)
[1;32m~\AppData\Local\Temp\ipykernel_19104\2288779447.py[0m in [0;36m<module>[1;34m[0m
[0;32m      8[0m [0mio[0m[1;33m.[0m[0mtemplates[0m[1;33m.[0m[0mdefault[0m [1;33m=[0m [1;34m'plotly_dark'[0m[1;33m[0m[1;33m[0m[0m
[0;32m      9[0m [1;33m[0m[0m
[1;32m---> 10[1;33m [0mmain_dataset[0m [1;33m=[0m [0mpd[0m[1;33m.[0m[0mread_pickle[0m[1;33m([0m[1;34m'processed_dataset.pkl'[0m[1;33m)[0m[1;33m[0m[1;33m[0m[0m
[0m
[1;32m~\anaconda3\envs\jupyterbook\lib\site-packages\pandas\io\pickle.py[0m in [0;36mread_pickle[1;34m(filepath_or_buffer, compression, storage_options)[0m
[0;32m    215[0m                     [1;31m# RawIOBase, BufferedIOBase, TextIOBase, TextIOWrapper, mmap]";[0m[1;33m[0m[1;33m[0m[1;33m[0m[0m
[0;32m    216[0m                     [1;31m# expected "IO[bytes]"[0m[1;33m[0m[1;33m[0m[1;33m[0m[0m
[1;32m--> 217[1;33m                     [1;32mreturn[0m [0mpickle[0m[1;33m.[0m[0mload[0m[1;33m([0m[0mhandles[0m[1;33m.[0m[0mhandle[0m[1;33m)[0m  [1;31m# type: ignore[arg-type][0m[1;33m[0m[1;33m[0m[0m
[0m[0;32m    218[0m             [1;32mexcept[0m [0mexcs_to_catch[0m[1;33m:[0m[1;33m[0m[1;33m[0m[0m
[0;32m    219[0m                 [1;31m# e.g.[0m[1;33m[0m[1;33m[0m[1;33m[0m[0m

[1;31mValueError[0m: unsupported pickle protocol: 5
ValueError: unsupported pickle protocol: 5

